<sdf version='1.7'>
  <world name='default'>
    <model name='ground_plane'>
      <static>1</static>
      <link name='link'>
        <collision name='collision'>
          <geometry>
            <plane>
              <normal>0 0 1</normal>
              <size>100 100</size>
            </plane>
          </geometry>
          <surface>
            <contact>
              <collide_bitmask>65535</collide_bitmask>
              <ode/>
            </contact>
            <friction>
              <ode>
                <mu>100</mu>
                <mu2>50</mu2>
              </ode>
              <torsional>
                <ode/>
              </torsional>
            </friction>
            <bounce/>
          </surface>
          <max_contacts>10</max_contacts>
        </collision>
        <visual name='visual'>
          <cast_shadows>0</cast_shadows>
          <geometry>
            <plane>
              <normal>0 0 1</normal>
              <size>100 100</size>
            </plane>
          </geometry>
          <material>
            <script>
              <uri>file://media/materials/scripts/gazebo.material</uri>
              <name>Gazebo/Grey</name>
            </script>
          </material>
        </visual>
        <self_collide>0</self_collide>
        <enable_wind>0</enable_wind>
        <kinematic>0</kinematic>
      </link>
      <pose>0 0 0 0 -0 0</pose>
      <plugin name='contact_plugin' filename='libContactPlugin.so'/>
    </model>
    <light name='sun' type='directional'>
      <cast_shadows>1</cast_shadows>
      <pose>0 0 10 0 -0 0</pose>
      <diffuse>0.8 0.8 0.8 1</diffuse>
      <specular>0.2 0.2 0.2 1</specular>
      <attenuation>
        <range>1000</range>
        <constant>0.9</constant>
        <linear>0.01</linear>
        <quadratic>0.001</quadratic>
      </attenuation>
      <direction>-0.5 0.1 -0.9</direction>
      <spot>
        <inner_angle>0</inner_angle>
        <outer_angle>0</outer_angle>
        <falloff>0</falloff>
      </spot>
    </light>
    <model name='box'>
      <static>1</static>
      <pose>1 1 0 0 0.1 0</pose>
      <link name='link'>
        <collision name='collision'>
          <geometry>
            <box>
              <size>1 0.5 0.1</size>
            </box>
          </geometry>
          <max_contacts>10</max_contacts>
          <surface>
            <contact>
              <ode/>
            </contact>
            <bounce/>
            <friction>
              <torsional>
                <ode/>
              </torsional>
              <ode/>
            </friction>
          </surface>
        </collision>
        <visual name='visual'>
          <geometry>
            <box>
              <size>1 0.5 0.1</size>
            </box>
          </geometry>
        </visual>
        <self_collide>0</self_collide>
        <enable_wind>0</enable_wind>
        <kinematic>0</kinematic>
      </link>
    </model>
    <gravity>0 0 -9.8</gravity>
    <magnetic_field>6e-06 2.3e-05 -4.2e-05</magnetic_field>
    <atmosphere type='adiabatic'/>
    <physics type='ode'>
      <max_step_size>0.001</max_step_size>
      <real_time_factor>1</real_time_factor>
      <real_time_update_rate>1000</real_time_update_rate>
    </physics>
    <scene>
      <ambient>0.4 0.4 0.4 1</ambient>
      <background>0.7 0.7 0.7 1</background>
      <shadows>1</shadows>
    </scene>
    <wind/>
    <spherical_coordinates>
      <surface_model>EARTH_WGS84</surface_model>
      <latitude_deg>0</latitude_deg>
      <longitude_deg>0</longitude_deg>
      <elevation>0</elevation>
      <heading_deg>0</heading_deg>
    </spherical_coordinates>
    <model name='ski'>
      <link name='base_link'>
        <inertial>
          <pose>-0 0 0.081029 0 -0 0</pose>
          <mass>3.1846</mass>
          <inertia>
            <ixx>0.049043</ixx>
            <ixy>-1.5821e-08</ixy>
            <ixz>-4.3995e-09</ixz>
            <iyy>0.083631</iyy>
            <iyz>1.8621e-10</iyz>
            <izz>0.13258</izz>
          </inertia>
        </inertial>
        <collision name='base_link_collision'>
          <pose>0 0 0 0 -0 0</pose>
          <geometry>
            <mesh>
              <scale>1 1 1</scale>
              <uri>/home/danya/thes/a1_sim_py/src/ski/meshes/base_link.STL</uri>
            </mesh>
          </geometry>
          <max_contacts>10</max_contacts>
          <surface>
            <contact>
              <ode/>
            </contact>
            <bounce/>
            <friction>
              <torsional>
                <ode/>
              </torsional>
              <ode/>
            </friction>
          </surface>
        </collision>
        <visual name='base_link_visual'>
          <pose>0 0 0 0 -0 0</pose>
          <geometry>
            <mesh>
              <scale>1 1 1</scale>
              <uri>/home/danya/thes/a1_sim_py/src/ski/meshes/base_link.STL</uri>
            </mesh>
          </geometry>
        </visual>
        <self_collide>0</self_collide>
        <enable_wind>0</enable_wind>
        <kinematic>0</kinematic>
      </link>
      <joint name='trj0' type='revolute'>
        <pose relative_to='base_link'>0.24845 0 0.025 0 0.38044 0</pose>
        <parent>base_link</parent>
        <child>tr0</child>
        <axis>
          <xyz>0 0 -1</xyz>
          <limit>
            <lower>-0.201799</lower>
            <upper>0.201799</upper>
            <effort>10</effort>
            <velocity>10</velocity>
          </limit>
          <dynamics>
            <spring_reference>0</spring_reference>
            <spring_stiffness>0</spring_stiffness>
          </dynamics>
        </axis>
      </joint>
      <link name='tr0'>
        <pose relative_to='trj0'>0 0 0 0 -0 0</pose>
        <inertial>
          <pose>-0.003948 1.4e-05 0.002543 0 -0 0</pose>
          <mass>0.054711</mass>
          <inertia>
            <ixx>7.6178e-05</ixx>
            <ixy>4.236e-09</ixy>
            <ixz>-1.6794e-07</ixz>
            <iyy>6.5079e-06</iyy>
            <iyz>3.528e-09</iyz>
            <izz>7.7065e-05</izz>
          </inertia>
        </inertial>
        <collision name='tr0_collision'>
          <pose>0 0 0 0 -0 0</pose>
          <geometry>
            <mesh>
              <scale>1 1 1</scale>
              <uri>/home/danya/thes/a1_sim_py/src/ski/meshes/tr0.STL</uri>
            </mesh>
          </geometry>
          <max_contacts>10</max_contacts>
          <surface>
            <contact>
              <ode/>
            </contact>
            <bounce/>
            <friction>
              <torsional>
                <ode/>
              </torsional>
              <ode/>
            </friction>
          </surface>
        </collision>
        <visual name='tr0_visual'>
          <pose>0 0 0 0 -0 0</pose>
          <geometry>
            <mesh>
              <scale>1 1 1</scale>
              <uri>/home/danya/thes/a1_sim_py/src/ski/meshes/tr0.STL</uri>
            </mesh>
          </geometry>
        </visual>
        <self_collide>0</self_collide>
        <enable_wind>0</enable_wind>
        <kinematic>0</kinematic>
      </link>
      <joint name='whj0' type='revolute'>
        <pose relative_to='tr0'>0 -0.079 0 0 -0.38044 0</pose>
        <parent>tr0</parent>
        <child>wh0</child>
        <axis>
          <xyz>0 1 0</xyz>
          <limit>
            <lower>-1e+16</lower>
            <upper>1e+16</upper>
          </limit>
          <dynamics>
            <spring_reference>0</spring_reference>
            <spring_stiffness>0</spring_stiffness>
          </dynamics>
        </axis>
      </joint>
      <link name='wh0'>
        <pose relative_to='whj0'>0 0 0 0 -0 0</pose>
        <inertial>
          <pose>0 0 0 0 -0 0</pose>
          <mass>0.049078</mass>
          <inertia>
            <ixx>1.141e-05</ixx>
            <ixy>0</ixy>
            <ixz>0</ixz>
            <iyy>1.6312e-05</iyy>
            <iyz>0</iyz>
            <izz>1.141e-05</izz>
          </inertia>
        </inertial>
        <collision name='wh0_collision'>
          <pose>0 0 0 0 -0 0</pose>
          <geometry>
            <mesh>
              <scale>1 1 1</scale>
              <uri>/home/danya/thes/a1_sim_py/src/ski/meshes/wh0.STL</uri>
            </mesh>
          </geometry>
          <max_contacts>10</max_contacts>
          <surface>
            <contact>
              <ode/>
            </contact>
            <bounce/>
            <friction>
              <torsional>
                <ode/>
              </torsional>
              <ode/>
            </friction>
          </surface>
        </collision>
        <visual name='wh0_visual'>
          <pose>0 0 0 0 -0 0</pose>
          <geometry>
            <mesh>
              <scale>1 1 1</scale>
              <uri>/home/danya/thes/a1_sim_py/src/ski/meshes/wh0.STL</uri>
            </mesh>
          </geometry>
        </visual>
        <self_collide>0</self_collide>
        <enable_wind>0</enable_wind>
        <kinematic>0</kinematic>
      </link>
      <joint name='whj1' type='revolute'>
        <pose relative_to='tr0'>0 0.079 0 0 -0.38044 0</pose>
        <parent>tr0</parent>
        <child>wh1</child>
        <axis>
          <xyz>0 1 0</xyz>
          <limit>
            <lower>-1e+16</lower>
            <upper>1e+16</upper>
          </limit>
          <dynamics>
            <spring_reference>0</spring_reference>
            <spring_stiffness>0</spring_stiffness>
          </dynamics>
        </axis>
      </joint>
      <link name='wh1'>
        <pose relative_to='whj1'>0 0 0 0 -0 0</pose>
        <inertial>
          <pose>0 0 0 0 -0 0</pose>
          <mass>0.049078</mass>
          <inertia>
            <ixx>1.141e-05</ixx>
            <ixy>0</ixy>
            <ixz>0</ixz>
            <iyy>1.6312e-05</iyy>
            <iyz>0</iyz>
            <izz>1.141e-05</izz>
          </inertia>
        </inertial>
        <collision name='wh1_collision'>
          <pose>0 0 0 0 -0 0</pose>
          <geometry>
            <mesh>
              <scale>1 1 1</scale>
              <uri>/home/danya/thes/a1_sim_py/src/ski/meshes/wh1.STL</uri>
            </mesh>
          </geometry>
          <max_contacts>10</max_contacts>
          <surface>
            <contact>
              <ode/>
            </contact>
            <bounce/>
            <friction>
              <torsional>
                <ode/>
              </torsional>
              <ode/>
            </friction>
          </surface>
        </collision>
        <visual name='wh1_visual'>
          <pose>0 0 0 0 -0 0</pose>
          <geometry>
            <mesh>
              <scale>1 1 1</scale>
              <uri>/home/danya/thes/a1_sim_py/src/ski/meshes/wh1.STL</uri>
            </mesh>
          </geometry>
        </visual>
        <self_collide>0</self_collide>
        <enable_wind>0</enable_wind>
        <kinematic>0</kinematic>
      </link>
      <joint name='trj1' type='revolute'>
        <pose relative_to='base_link'>-0.24845 0 0.025 0 0.38044 -3.14159</pose>
        <parent>base_link</parent>
        <child>tr1</child>
        <axis>
          <xyz>0 0 -1</xyz>
          <limit>
            <lower>-0.201799</lower>
            <upper>0.201799</upper>
            <effort>10</effort>
            <velocity>10</velocity>
          </limit>
          <dynamics>
            <spring_reference>0</spring_reference>
            <spring_stiffness>0</spring_stiffness>
          </dynamics>
        </axis>
      </joint>
      <link name='tr1'>
        <pose relative_to='trj1'>0 0 0 0 -0 0</pose>
        <inertial>
          <pose>0 0 0 0 -0 0</pose>
          <mass>0.054711</mass>
          <inertia>
            <ixx>7.6178e-05</ixx>
            <ixy>0</ixy>
            <ixz>0</ixz>
            <iyy>6.5079e-06</iyy>
            <iyz>0</iyz>
            <izz>7.7065e-05</izz>
          </inertia>
        </inertial>
        <collision name='tr1_collision'>
          <pose>0 0 0 0 -0 0</pose>
          <geometry>
            <mesh>
              <scale>1 1 1</scale>
              <uri>/home/danya/thes/a1_sim_py/src/ski/meshes/tr1.STL</uri>
            </mesh>
          </geometry>
          <max_contacts>10</max_contacts>
          <surface>
            <contact>
              <ode/>
            </contact>
            <bounce/>
            <friction>
              <torsional>
                <ode/>
              </torsional>
              <ode/>
            </friction>
          </surface>
        </collision>
        <visual name='tr1_visual'>
          <pose>0 0 0 0 -0 0</pose>
          <geometry>
            <mesh>
              <scale>1 1 1</scale>
              <uri>/home/danya/thes/a1_sim_py/src/ski/meshes/tr1.STL</uri>
            </mesh>
          </geometry>
        </visual>
        <self_collide>0</self_collide>
        <enable_wind>0</enable_wind>
        <kinematic>0</kinematic>
      </link>
      <joint name='whj2' type='revolute'>
        <pose relative_to='tr1'>0 0.079 0 0 0.38044 -3.14159</pose>
        <parent>tr1</parent>
        <child>wh2</child>
        <axis>
          <xyz>0 1 0</xyz>
          <limit>
            <lower>-1e+16</lower>
            <upper>1e+16</upper>
          </limit>
          <dynamics>
            <spring_reference>0</spring_reference>
            <spring_stiffness>0</spring_stiffness>
          </dynamics>
        </axis>
      </joint>
      <link name='wh2'>
        <pose relative_to='whj2'>0 0 0 0 -0 0</pose>
        <inertial>
          <pose>0 0 0 0 -0 0</pose>
          <mass>0.049078</mass>
          <inertia>
            <ixx>1.141e-05</ixx>
            <ixy>0</ixy>
            <ixz>0</ixz>
            <iyy>1.6312e-05</iyy>
            <iyz>0</iyz>
            <izz>1.141e-05</izz>
          </inertia>
        </inertial>
        <collision name='wh2_collision'>
          <pose>0 0 0 0 -0 0</pose>
          <geometry>
            <mesh>
              <scale>1 1 1</scale>
              <uri>/home/danya/thes/a1_sim_py/src/ski/meshes/wh2.STL</uri>
            </mesh>
          </geometry>
          <max_contacts>10</max_contacts>
          <surface>
            <contact>
              <ode/>
            </contact>
            <bounce/>
            <friction>
              <torsional>
                <ode/>
              </torsional>
              <ode/>
            </friction>
          </surface>
        </collision>
        <visual name='wh2_visual'>
          <pose>0 0 0 0 -0 0</pose>
          <geometry>
            <mesh>
              <scale>1 1 1</scale>
              <uri>/home/danya/thes/a1_sim_py/src/ski/meshes/wh2.STL</uri>
            </mesh>
          </geometry>
        </visual>
        <self_collide>0</self_collide>
        <enable_wind>0</enable_wind>
        <kinematic>0</kinematic>
      </link>
      <joint name='whj3' type='revolute'>
        <pose relative_to='tr1'>0 -0.079 0 0 0.38044 -3.14159</pose>
        <parent>tr1</parent>
        <child>wh3</child>
        <axis>
          <xyz>0 1 0</xyz>
          <limit>
            <lower>-1e+16</lower>
            <upper>1e+16</upper>
          </limit>
          <dynamics>
            <spring_reference>0</spring_reference>
            <spring_stiffness>0</spring_stiffness>
          </dynamics>
        </axis>
      </joint>
      <link name='wh3'>
        <pose relative_to='whj3'>0 0 0 0 -0 0</pose>
        <inertial>
          <pose>0 0 0 0 -0 0</pose>
          <mass>0.049078</mass>
          <inertia>
            <ixx>1.141e-05</ixx>
            <ixy>0</ixy>
            <ixz>0</ixz>
            <iyy>1.6312e-05</iyy>
            <iyz>0</iyz>
            <izz>1.141e-05</izz>
          </inertia>
        </inertial>
        <collision name='wh3_collision'>
          <pose>0 0 0 0 -0 0</pose>
          <geometry>
            <mesh>
              <scale>1 1 1</scale>
              <uri>/home/danya/thes/a1_sim_py/src/ski/meshes/wh3.STL</uri>
            </mesh>
          </geometry>
          <max_contacts>10</max_contacts>
          <surface>
            <contact>
              <ode/>
            </contact>
            <bounce/>
            <friction>
              <torsional>
                <ode/>
              </torsional>
              <ode/>
            </friction>
          </surface>
        </collision>
        <visual name='wh3_visual'>
          <pose>0 0 0 0 -0 0</pose>
          <geometry>
            <mesh>
              <scale>1 1 1</scale>
              <uri>/home/danya/thes/a1_sim_py/src/ski/meshes/wh3.STL</uri>
            </mesh>
          </geometry>
        </visual>
        <self_collide>0</self_collide>
        <enable_wind>0</enable_wind>
        <kinematic>0</kinematic>
      </link>
      <plugin name='trj0_torsional_spring' filename='libgazebo_joint_torsional_spring.so'>
        <kx>20.0</kx>
        <set_point>0</set_point>
        <joint>trj0</joint>
        <robotNamespace>/</robotNamespace>
      </plugin>
      <plugin name='trj1_torsional_spring' filename='libgazebo_joint_torsional_spring.so'>
        <kx>20.0</kx>
        <set_point>0</set_point>
        <joint>trj1</joint>
        <robotNamespace>/</robotNamespace>
      </plugin>
      <pose>2 0 0 0 -0 0</pose>
    </model>
    <model name='a1_gazebo'>
      <link name='base'>
        <inertial>
          <pose>0.012728 0.002186 0.000515 0 -0 0</pose>
          <mass>4.714</mass>
          <inertia>
            <ixx>0.0169399</ixx>
            <ixy>8.38742e-05</ixy>
            <ixz>0.000597672</ixz>
            <iyy>0.0566792</iyy>
            <iyz>2.51329e-05</iyz>
            <izz>0.0648138</izz>
          </inertia>
        </inertial>
        <collision name='base_fixed_joint_lump__trunk_collision'>
          <pose>0 0 0 0 -0 0</pose>
          <geometry>
            <box>
              <size>0.267 0.194 0.114</size>
            </box>
          </geometry>
          <surface>
            <contact>
              <ode/>
            </contact>
            <friction>
              <ode/>
              <torsional>
                <ode/>
              </torsional>
            </friction>
            <bounce/>
          </surface>
          <max_contacts>10</max_contacts>
        </collision>
        <collision name='base_fixed_joint_lump__imu_link_collision_1'>
          <pose>0 0 0 0 -0 0</pose>
          <geometry>
            <box>
              <size>0.001 0.001 0.001</size>
            </box>
          </geometry>
          <max_contacts>10</max_contacts>
          <surface>
            <contact>
              <ode/>
            </contact>
            <bounce/>
            <friction>
              <torsional>
                <ode/>
              </torsional>
              <ode/>
            </friction>
          </surface>
        </collision>
        <visual name='base_visual'>
          <pose>0 0 0 0 -0 0</pose>
          <geometry>
            <box>
              <size>0.001 0.001 0.001</size>
            </box>
          </geometry>
        </visual>
        <visual name='base_fixed_joint_lump__trunk_visual_1'>
          <pose>0 0 0 0 -0 0</pose>
          <geometry>
            <mesh>
              <scale>1 1 1</scale>
              <uri>/home/danya/thes/a1_sim_py/src/a1_description/meshes/trunk.dae</uri>
            </mesh>
          </geometry>
        </visual>
        <visual name='base_fixed_joint_lump__imu_link_visual_2'>
          <pose>0 0 0 0 -0 0</pose>
          <geometry>
            <box>
              <size>0.001 0.001 0.001</size>
            </box>
          </geometry>
        </visual>
        <gravity>1</gravity>
        <sensor name='imu_sensor' type='imu'>
          <always_on>1</always_on>
          <update_rate>100</update_rate>
          <visualize>1</visualize>
          <topic>__default_topic__</topic>
          <plugin name='imu_plugin' filename='libgazebo_ros_imu_sensor.so'>
            <topicName>a1_imu/base_link_orientation</topicName>
            <bodyName>imu_link</bodyName>
            <updateRateHZ>15.0</updateRateHZ>
            <gaussianNoise>0.0</gaussianNoise>
            <xyzOffset>0 0 0</xyzOffset>
            <rpyOffset>0 0 0</rpyOffset>
            <frameName>trunk</frameName>
            <initialOrientationAsReference>0</initialOrientationAsReference>
            <robotNamespace>/</robotNamespace>
          </plugin>
          <pose>0 0 0 0 -0 0</pose>
          <imu/>
        </sensor>
        <self_collide>0</self_collide>
        <enable_wind>0</enable_wind>
        <kinematic>0</kinematic>
      </link>
      <joint name='FL_hip_joint' type='revolute'>
        <pose relative_to='base'>0.183 0.047 0 0 -0 0</pose>
        <parent>base</parent>
        <child>FL_hip</child>
        <axis>
          <xyz>1 0 0</xyz>
          <limit>
            <lower>-0.802851</lower>
            <upper>0.802851</upper>
            <effort>20</effort>
            <velocity>52.4</velocity>
          </limit>
          <dynamics>
            <damping>0</damping>
            <friction>0</friction>
            <spring_reference>0</spring_reference>
            <spring_stiffness>0</spring_stiffness>
          </dynamics>
        </axis>
      </joint>
      <link name='FL_hip'>
        <pose relative_to='FL_hip_joint'>0 0 0 0 -0 0</pose>
        <inertial>
          <pose>-0.003311 0.000635 3.1e-05 0 -0 0</pose>
          <mass>0.696</mass>
          <inertia>
            <ixx>0.000469246</ixx>
            <ixy>-9.409e-06</ixy>
            <ixz>-3.42e-07</ixz>
            <iyy>0.00080749</iyy>
            <iyz>-4.66e-07</iyz>
            <izz>0.000552929</izz>
          </inertia>
        </inertial>
        <collision name='FL_hip_collision'>
          <pose>0 0 0 1.5708 -0 0</pose>
          <geometry>
            <cylinder>
              <length>0.04</length>
              <radius>0.046</radius>
            </cylinder>
          </geometry>
          <max_contacts>10</max_contacts>
          <surface>
            <contact>
              <ode/>
            </contact>
            <bounce/>
            <friction>
              <torsional>
                <ode/>
              </torsional>
              <ode/>
            </friction>
          </surface>
        </collision>
        <collision name='FL_hip_fixed_joint_lump__FL_thigh_shoulder_collision_1'>
          <pose>0 0.081 0 1.5708 -0 0</pose>
          <geometry>
            <cylinder>
              <length>0.032</length>
              <radius>0.041</radius>
            </cylinder>
          </geometry>
          <max_contacts>10</max_contacts>
          <surface>
            <contact>
              <ode/>
            </contact>
            <bounce/>
            <friction>
              <torsional>
                <ode/>
              </torsional>
              <ode/>
            </friction>
          </surface>
        </collision>
        <visual name='FL_hip_visual'>
          <pose>0 0 0 0 -0 0</pose>
          <geometry>
            <mesh>
              <scale>1 1 1</scale>
              <uri>/home/danya/thes/a1_sim_py/src/a1_description/meshes/hip.dae</uri>
            </mesh>
          </geometry>
        </visual>
        <self_collide>0</self_collide>
        <enable_wind>0</enable_wind>
        <kinematic>0</kinematic>
      </link>
      <joint name='FL_thigh_joint' type='revolute'>
        <pose relative_to='FL_hip'>0 0.08505 0 0 -0 0</pose>
        <parent>FL_hip</parent>
        <child>FL_thigh</child>
        <axis>
          <xyz>0 1 0</xyz>
          <limit>
            <lower>-1.0472</lower>
            <upper>4.18879</upper>
            <effort>55</effort>
            <velocity>28.6</velocity>
          </limit>
          <dynamics>
            <damping>0</damping>
            <friction>0</friction>
            <spring_reference>0</spring_reference>
            <spring_stiffness>0</spring_stiffness>
          </dynamics>
        </axis>
      </joint>
      <link name='FL_thigh'>
        <pose relative_to='FL_thigh_joint'>0 0 0 0 -0 0</pose>
        <inertial>
          <pose>-0.003237 -0.022327 -0.027326 0 -0 0</pose>
          <mass>1.013</mass>
          <inertia>
            <ixx>0.00552906</ixx>
            <ixy>4.825e-06</ixy>
            <ixz>0.000343869</ixz>
            <iyy>0.00513934</iyy>
            <iyz>2.2448e-05</iyz>
            <izz>0.00136779</izz>
          </inertia>
        </inertial>
        <collision name='FL_thigh_collision'>
          <pose>0 0 -0.1 3.14159 1.57079 3.14159</pose>
          <geometry>
            <box>
              <size>0.2 0.0245 0.034</size>
            </box>
          </geometry>
          <max_contacts>10</max_contacts>
          <surface>
            <contact>
              <ode/>
            </contact>
            <bounce/>
            <friction>
              <torsional>
                <ode/>
              </torsional>
              <ode/>
            </friction>
          </surface>
        </collision>
        <visual name='FL_thigh_visual'>
          <pose>0 0 0 0 -0 0</pose>
          <geometry>
            <mesh>
              <scale>1 1 1</scale>
              <uri>/home/danya/thes/a1_sim_py/src/a1_description/meshes/thigh.dae</uri>
            </mesh>
          </geometry>
        </visual>
        <self_collide>0</self_collide>
        <enable_wind>0</enable_wind>
        <kinematic>0</kinematic>
      </link>
      <joint name='FL_calf_joint' type='revolute'>
        <pose relative_to='FL_thigh'>0 0 -0.2 0 -0 0</pose>
        <parent>FL_thigh</parent>
        <child>FL_calf</child>
        <axis>
          <xyz>0 1 0</xyz>
          <limit>
            <lower>-2.69653</lower>
            <upper>-0.916298</upper>
            <effort>55</effort>
            <velocity>28.6</velocity>
          </limit>
          <dynamics>
            <damping>0</damping>
            <friction>0</friction>
            <spring_reference>0</spring_reference>
            <spring_stiffness>0</spring_stiffness>
          </dynamics>
        </axis>
      </joint>
      <link name='FL_calf'>
        <pose relative_to='FL_calf_joint'>0 0 0 0 -0 0</pose>
        <inertial>
          <pose>0.004727 0 -0.131975 0 -0 0</pose>
          <mass>0.226</mass>
          <inertia>
            <ixx>0.00338557</ixx>
            <ixy>0</ixy>
            <ixz>-0.000167427</ixz>
            <iyy>0.00340344</iyy>
            <iyz>0</iyz>
            <izz>4.38509e-05</izz>
          </inertia>
        </inertial>
        <collision name='FL_calf_collision'>
          <pose>0 0 -0.1 3.14159 1.57079 3.14159</pose>
          <geometry>
            <box>
              <size>0.2 0.016 0.016</size>
            </box>
          </geometry>
          <max_contacts>10</max_contacts>
          <surface>
            <contact>
              <ode/>
            </contact>
            <bounce/>
            <friction>
              <torsional>
                <ode/>
              </torsional>
              <ode/>
            </friction>
          </surface>
        </collision>
        <collision name='FL_calf_fixed_joint_lump__FL_foot_collision_1'>
          <pose>0 0 -0.2 0 -0 0</pose>
          <geometry>
            <sphere>
              <radius>0.02</radius>
            </sphere>
          </geometry>
          <surface>
            <contact>
              <ode>
                <kp>1e+06</kp>
                <kd>100</kd>
                <min_depth>0.0002</min_depth>
              </ode>
            </contact>
            <friction>
              <ode>
                <mu>1</mu>
                <mu2>1</mu2>
              </ode>
              <torsional>
                <ode/>
              </torsional>
            </friction>
            <bounce/>
          </surface>
          <max_contacts>10</max_contacts>
        </collision>
        <visual name='FL_calf_visual'>
          <pose>0 0 0 0 -0 0</pose>
          <geometry>
            <mesh>
              <scale>1 1 1</scale>
              <uri>/home/danya/thes/a1_sim_py/src/a1_description/meshes/calf.dae</uri>
            </mesh>
          </geometry>
        </visual>
        <visual name='FL_calf_fixed_joint_lump__FL_foot_visual_1'>
          <pose>0 0 -0.2 0 -0 0</pose>
          <geometry>
            <sphere>
              <radius>0.01</radius>
            </sphere>
          </geometry>
        </visual>
        <self_collide>0</self_collide>
        <enable_wind>0</enable_wind>
        <kinematic>0</kinematic>
      </link>
      <joint name='FR_hip_joint' type='revolute'>
        <pose relative_to='base'>0.183 -0.047 0 0 -0 0</pose>
        <parent>base</parent>
        <child>FR_hip</child>
        <axis>
          <xyz>1 0 0</xyz>
          <limit>
            <lower>-0.802851</lower>
            <upper>0.802851</upper>
            <effort>20</effort>
            <velocity>52.4</velocity>
          </limit>
          <dynamics>
            <damping>0</damping>
            <friction>0</friction>
            <spring_reference>0</spring_reference>
            <spring_stiffness>0</spring_stiffness>
          </dynamics>
        </axis>
      </joint>
      <link name='FR_hip'>
        <pose relative_to='FR_hip_joint'>0 0 0 0 -0 0</pose>
        <inertial>
          <pose>-0.003311 -0.000635 3.1e-05 0 -0 0</pose>
          <mass>0.696</mass>
          <inertia>
            <ixx>0.000469246</ixx>
            <ixy>9.409e-06</ixy>
            <ixz>-3.42e-07</ixz>
            <iyy>0.00080749</iyy>
            <iyz>4.66e-07</iyz>
            <izz>0.000552929</izz>
          </inertia>
        </inertial>
        <collision name='FR_hip_collision'>
          <pose>0 0 0 1.5708 -0 0</pose>
          <geometry>
            <cylinder>
              <length>0.04</length>
              <radius>0.046</radius>
            </cylinder>
          </geometry>
          <max_contacts>10</max_contacts>
          <surface>
            <contact>
              <ode/>
            </contact>
            <bounce/>
            <friction>
              <torsional>
                <ode/>
              </torsional>
              <ode/>
            </friction>
          </surface>
        </collision>
        <collision name='FR_hip_fixed_joint_lump__FR_thigh_shoulder_collision_1'>
          <pose>0 -0.081 0 1.5708 -0 0</pose>
          <geometry>
            <cylinder>
              <length>0.032</length>
              <radius>0.041</radius>
            </cylinder>
          </geometry>
          <max_contacts>10</max_contacts>
          <surface>
            <contact>
              <ode/>
            </contact>
            <bounce/>
            <friction>
              <torsional>
                <ode/>
              </torsional>
              <ode/>
            </friction>
          </surface>
        </collision>
        <visual name='FR_hip_visual'>
          <pose>0 0 0 -3.14159 0 0</pose>
          <geometry>
            <mesh>
              <scale>1 1 1</scale>
              <uri>/home/danya/thes/a1_sim_py/src/a1_description/meshes/hip.dae</uri>
            </mesh>
          </geometry>
        </visual>
        <self_collide>0</self_collide>
        <enable_wind>0</enable_wind>
        <kinematic>0</kinematic>
      </link>
      <joint name='FR_thigh_joint' type='revolute'>
        <pose relative_to='FR_hip'>0 -0.08505 0 0 -0 0</pose>
        <parent>FR_hip</parent>
        <child>FR_thigh</child>
        <axis>
          <xyz>0 1 0</xyz>
          <limit>
            <lower>-1.0472</lower>
            <upper>4.18879</upper>
            <effort>55</effort>
            <velocity>28.6</velocity>
          </limit>
          <dynamics>
            <damping>0</damping>
            <friction>0</friction>
            <spring_reference>0</spring_reference>
            <spring_stiffness>0</spring_stiffness>
          </dynamics>
        </axis>
      </joint>
      <link name='FR_thigh'>
        <pose relative_to='FR_thigh_joint'>0 0 0 0 -0 0</pose>
        <inertial>
          <pose>-0.003237 0.022327 -0.027326 0 -0 0</pose>
          <mass>1.013</mass>
          <inertia>
            <ixx>0.00552906</ixx>
            <ixy>-4.825e-06</ixy>
            <ixz>0.000343869</ixz>
            <iyy>0.00513934</iyy>
            <iyz>-2.2448e-05</iyz>
            <izz>0.00136779</izz>
          </inertia>
        </inertial>
        <collision name='FR_thigh_collision'>
          <pose>0 0 -0.1 3.14159 1.57079 3.14159</pose>
          <geometry>
            <box>
              <size>0.2 0.0245 0.034</size>
            </box>
          </geometry>
          <max_contacts>10</max_contacts>
          <surface>
            <contact>
              <ode/>
            </contact>
            <bounce/>
            <friction>
              <torsional>
                <ode/>
              </torsional>
              <ode/>
            </friction>
          </surface>
        </collision>
        <visual name='FR_thigh_visual'>
          <pose>0 0 0 0 -0 0</pose>
          <geometry>
            <mesh>
              <scale>1 1 1</scale>
              <uri>/home/danya/thes/a1_sim_py/src/a1_description/meshes/thigh_mirror.dae</uri>
            </mesh>
          </geometry>
        </visual>
        <self_collide>0</self_collide>
        <enable_wind>0</enable_wind>
        <kinematic>0</kinematic>
      </link>
      <joint name='FR_calf_joint' type='revolute'>
        <pose relative_to='FR_thigh'>0 0 -0.2 0 -0 0</pose>
        <parent>FR_thigh</parent>
        <child>FR_calf</child>
        <axis>
          <xyz>0 1 0</xyz>
          <limit>
            <lower>-2.69653</lower>
            <upper>-0.916298</upper>
            <effort>55</effort>
            <velocity>28.6</velocity>
          </limit>
          <dynamics>
            <damping>0</damping>
            <friction>0</friction>
            <spring_reference>0</spring_reference>
            <spring_stiffness>0</spring_stiffness>
          </dynamics>
        </axis>
      </joint>
      <link name='FR_calf'>
        <pose relative_to='FR_calf_joint'>0 0 0 0 -0 0</pose>
        <inertial>
          <pose>0.004727 0 -0.131975 0 -0 0</pose>
          <mass>0.226</mass>
          <inertia>
            <ixx>0.00338557</ixx>
            <ixy>0</ixy>
            <ixz>-0.000167427</ixz>
            <iyy>0.00340344</iyy>
            <iyz>0</iyz>
            <izz>4.38509e-05</izz>
          </inertia>
        </inertial>
        <collision name='FR_calf_collision'>
          <pose>0 0 -0.1 3.14159 1.57079 3.14159</pose>
          <geometry>
            <box>
              <size>0.2 0.016 0.016</size>
            </box>
          </geometry>
          <max_contacts>10</max_contacts>
          <surface>
            <contact>
              <ode/>
            </contact>
            <bounce/>
            <friction>
              <torsional>
                <ode/>
              </torsional>
              <ode/>
            </friction>
          </surface>
        </collision>
        <collision name='FR_calf_fixed_joint_lump__FR_foot_collision_1'>
          <pose>0 0 -0.2 0 -0 0</pose>
          <geometry>
            <sphere>
              <radius>0.02</radius>
            </sphere>
          </geometry>
          <surface>
            <contact>
              <ode>
                <kp>1e+06</kp>
                <kd>100</kd>
                <min_depth>0.0002</min_depth>
              </ode>
            </contact>
            <friction>
              <ode>
                <mu>1</mu>
                <mu2>1</mu2>
              </ode>
              <torsional>
                <ode/>
              </torsional>
            </friction>
            <bounce/>
          </surface>
          <max_contacts>10</max_contacts>
        </collision>
        <visual name='FR_calf_visual'>
          <pose>0 0 0 0 -0 0</pose>
          <geometry>
            <mesh>
              <scale>1 1 1</scale>
              <uri>/home/danya/thes/a1_sim_py/src/a1_description/meshes/calf.dae</uri>
            </mesh>
          </geometry>
        </visual>
        <visual name='FR_calf_fixed_joint_lump__FR_foot_visual_1'>
          <pose>0 0 -0.2 0 -0 0</pose>
          <geometry>
            <sphere>
              <radius>0.01</radius>
            </sphere>
          </geometry>
        </visual>
        <self_collide>0</self_collide>
        <enable_wind>0</enable_wind>
        <kinematic>0</kinematic>
      </link>
      <joint name='RL_hip_joint' type='revolute'>
        <pose relative_to='base'>-0.183 0.047 0 0 -0 0</pose>
        <parent>base</parent>
        <child>RL_hip</child>
        <axis>
          <xyz>1 0 0</xyz>
          <limit>
            <lower>-0.802851</lower>
            <upper>0.802851</upper>
            <effort>20</effort>
            <velocity>52.4</velocity>
          </limit>
          <dynamics>
            <damping>0</damping>
            <friction>0</friction>
            <spring_reference>0</spring_reference>
            <spring_stiffness>0</spring_stiffness>
          </dynamics>
        </axis>
      </joint>
      <link name='RL_hip'>
        <pose relative_to='RL_hip_joint'>0 0 0 0 -0 0</pose>
        <inertial>
          <pose>0.003311 0.000635 3.1e-05 0 -0 0</pose>
          <mass>0.696</mass>
          <inertia>
            <ixx>0.000469246</ixx>
            <ixy>9.409e-06</ixy>
            <ixz>3.42e-07</ixz>
            <iyy>0.00080749</iyy>
            <iyz>-4.66e-07</iyz>
            <izz>0.000552929</izz>
          </inertia>
        </inertial>
        <collision name='RL_hip_collision'>
          <pose>0 0 0 1.5708 -0 0</pose>
          <geometry>
            <cylinder>
              <length>0.04</length>
              <radius>0.046</radius>
            </cylinder>
          </geometry>
          <max_contacts>10</max_contacts>
          <surface>
            <contact>
              <ode/>
            </contact>
            <bounce/>
            <friction>
              <torsional>
                <ode/>
              </torsional>
              <ode/>
            </friction>
          </surface>
        </collision>
        <collision name='RL_hip_fixed_joint_lump__RL_thigh_shoulder_collision_1'>
          <pose>0 0.081 0 1.5708 -0 0</pose>
          <geometry>
            <cylinder>
              <length>0.032</length>
              <radius>0.041</radius>
            </cylinder>
          </geometry>
          <max_contacts>10</max_contacts>
          <surface>
            <contact>
              <ode/>
            </contact>
            <bounce/>
            <friction>
              <torsional>
                <ode/>
              </torsional>
              <ode/>
            </friction>
          </surface>
        </collision>
        <visual name='RL_hip_visual'>
          <pose>0 0 0 3.14159 -0 3.14159</pose>
          <geometry>
            <mesh>
              <scale>1 1 1</scale>
              <uri>/home/danya/thes/a1_sim_py/src/a1_description/meshes/hip.dae</uri>
            </mesh>
          </geometry>
        </visual>
        <self_collide>0</self_collide>
        <enable_wind>0</enable_wind>
        <kinematic>0</kinematic>
      </link>
      <joint name='RL_thigh_joint' type='revolute'>
        <pose relative_to='RL_hip'>0 0.08505 0 0 -0 0</pose>
        <parent>RL_hip</parent>
        <child>RL_thigh</child>
        <axis>
          <xyz>0 1 0</xyz>
          <limit>
            <lower>-1.0472</lower>
            <upper>4.18879</upper>
            <effort>55</effort>
            <velocity>28.6</velocity>
          </limit>
          <dynamics>
            <damping>0</damping>
            <friction>0</friction>
            <spring_reference>0</spring_reference>
            <spring_stiffness>0</spring_stiffness>
          </dynamics>
        </axis>
      </joint>
      <link name='RL_thigh'>
        <pose relative_to='RL_thigh_joint'>0 0 0 0 -0 0</pose>
        <inertial>
          <pose>-0.003237 -0.022327 -0.027326 0 -0 0</pose>
          <mass>1.013</mass>
          <inertia>
            <ixx>0.00552906</ixx>
            <ixy>4.825e-06</ixy>
            <ixz>0.000343869</ixz>
            <iyy>0.00513934</iyy>
            <iyz>2.2448e-05</iyz>
            <izz>0.00136779</izz>
          </inertia>
        </inertial>
        <collision name='RL_thigh_collision'>
          <pose>0 0 -0.1 3.14159 1.57079 3.14159</pose>
          <geometry>
            <box>
              <size>0.2 0.0245 0.034</size>
            </box>
          </geometry>
          <max_contacts>10</max_contacts>
          <surface>
            <contact>
              <ode/>
            </contact>
            <bounce/>
            <friction>
              <torsional>
                <ode/>
              </torsional>
              <ode/>
            </friction>
          </surface>
        </collision>
        <visual name='RL_thigh_visual'>
          <pose>0 0 0 0 -0 0</pose>
          <geometry>
            <mesh>
              <scale>1 1 1</scale>
              <uri>/home/danya/thes/a1_sim_py/src/a1_description/meshes/thigh.dae</uri>
            </mesh>
          </geometry>
        </visual>
        <self_collide>0</self_collide>
        <enable_wind>0</enable_wind>
        <kinematic>0</kinematic>
      </link>
      <joint name='RL_calf_joint' type='revolute'>
        <pose relative_to='RL_thigh'>0 0 -0.2 0 -0 0</pose>
        <parent>RL_thigh</parent>
        <child>RL_calf</child>
        <axis>
          <xyz>0 1 0</xyz>
          <limit>
            <lower>-2.69653</lower>
            <upper>-0.916298</upper>
            <effort>55</effort>
            <velocity>28.6</velocity>
          </limit>
          <dynamics>
            <damping>0</damping>
            <friction>0</friction>
            <spring_reference>0</spring_reference>
            <spring_stiffness>0</spring_stiffness>
          </dynamics>
        </axis>
      </joint>
      <link name='RL_calf'>
        <pose relative_to='RL_calf_joint'>0 0 0 0 -0 0</pose>
        <inertial>
          <pose>0.004727 0 -0.131975 0 -0 0</pose>
          <mass>0.226</mass>
          <inertia>
            <ixx>0.00338557</ixx>
            <ixy>0</ixy>
            <ixz>-0.000167427</ixz>
            <iyy>0.00340344</iyy>
            <iyz>0</iyz>
            <izz>4.38509e-05</izz>
          </inertia>
        </inertial>
        <collision name='RL_calf_collision'>
          <pose>0 0 -0.1 3.14159 1.57079 3.14159</pose>
          <geometry>
            <box>
              <size>0.2 0.016 0.016</size>
            </box>
          </geometry>
          <max_contacts>10</max_contacts>
          <surface>
            <contact>
              <ode/>
            </contact>
            <bounce/>
            <friction>
              <torsional>
                <ode/>
              </torsional>
              <ode/>
            </friction>
          </surface>
        </collision>
        <collision name='RL_calf_fixed_joint_lump__RL_foot_collision_1'>
          <pose>0 0 -0.2 0 -0 0</pose>
          <geometry>
            <sphere>
              <radius>0.02</radius>
            </sphere>
          </geometry>
          <surface>
            <contact>
              <ode>
                <kp>1e+06</kp>
                <kd>100</kd>
                <min_depth>0.0002</min_depth>
              </ode>
            </contact>
            <friction>
              <ode>
                <mu>1</mu>
                <mu2>1</mu2>
              </ode>
              <torsional>
                <ode/>
              </torsional>
            </friction>
            <bounce/>
          </surface>
          <max_contacts>10</max_contacts>
        </collision>
        <visual name='RL_calf_visual'>
          <pose>0 0 0 0 -0 0</pose>
          <geometry>
            <mesh>
              <scale>1 1 1</scale>
              <uri>/home/danya/thes/a1_sim_py/src/a1_description/meshes/calf.dae</uri>
            </mesh>
          </geometry>
        </visual>
        <visual name='RL_calf_fixed_joint_lump__RL_foot_visual_1'>
          <pose>0 0 -0.2 0 -0 0</pose>
          <geometry>
            <sphere>
              <radius>0.01</radius>
            </sphere>
          </geometry>
        </visual>
        <self_collide>0</self_collide>
        <enable_wind>0</enable_wind>
        <kinematic>0</kinematic>
      </link>
      <joint name='RR_hip_joint' type='revolute'>
        <pose relative_to='base'>-0.183 -0.047 0 0 -0 0</pose>
        <parent>base</parent>
        <child>RR_hip</child>
        <axis>
          <xyz>1 0 0</xyz>
          <limit>
            <lower>-0.802851</lower>
            <upper>0.802851</upper>
            <effort>20</effort>
            <velocity>52.4</velocity>
          </limit>
          <dynamics>
            <damping>0</damping>
            <friction>0</friction>
            <spring_reference>0</spring_reference>
            <spring_stiffness>0</spring_stiffness>
          </dynamics>
        </axis>
      </joint>
      <link name='RR_hip'>
        <pose relative_to='RR_hip_joint'>0 0 0 0 -0 0</pose>
        <inertial>
          <pose>0.003311 -0.000635 3.1e-05 0 -0 0</pose>
          <mass>0.696</mass>
          <inertia>
            <ixx>0.000469246</ixx>
            <ixy>-9.409e-06</ixy>
            <ixz>3.42e-07</ixz>
            <iyy>0.00080749</iyy>
            <iyz>4.66e-07</iyz>
            <izz>0.000552929</izz>
          </inertia>
        </inertial>
        <collision name='RR_hip_collision'>
          <pose>0 0 0 1.5708 -0 0</pose>
          <geometry>
            <cylinder>
              <length>0.04</length>
              <radius>0.046</radius>
            </cylinder>
          </geometry>
          <max_contacts>10</max_contacts>
          <surface>
            <contact>
              <ode/>
            </contact>
            <bounce/>
            <friction>
              <torsional>
                <ode/>
              </torsional>
              <ode/>
            </friction>
          </surface>
        </collision>
        <collision name='RR_hip_fixed_joint_lump__RR_thigh_shoulder_collision_1'>
          <pose>0 -0.081 0 1.5708 -0 0</pose>
          <geometry>
            <cylinder>
              <length>0.032</length>
              <radius>0.041</radius>
            </cylinder>
          </geometry>
          <max_contacts>10</max_contacts>
          <surface>
            <contact>
              <ode/>
            </contact>
            <bounce/>
            <friction>
              <torsional>
                <ode/>
              </torsional>
              <ode/>
            </friction>
          </surface>
        </collision>
        <visual name='RR_hip_visual'>
          <pose>0 0 0 0 -0 3.14159</pose>
          <geometry>
            <mesh>
              <scale>1 1 1</scale>
              <uri>/home/danya/thes/a1_sim_py/src/a1_description/meshes/hip.dae</uri>
            </mesh>
          </geometry>
        </visual>
        <self_collide>0</self_collide>
        <enable_wind>0</enable_wind>
        <kinematic>0</kinematic>
      </link>
      <joint name='RR_thigh_joint' type='revolute'>
        <pose relative_to='RR_hip'>0 -0.08505 0 0 -0 0</pose>
        <parent>RR_hip</parent>
        <child>RR_thigh</child>
        <axis>
          <xyz>0 1 0</xyz>
          <limit>
            <lower>-1.0472</lower>
            <upper>4.18879</upper>
            <effort>55</effort>
            <velocity>28.6</velocity>
          </limit>
          <dynamics>
            <damping>0</damping>
            <friction>0</friction>
            <spring_reference>0</spring_reference>
            <spring_stiffness>0</spring_stiffness>
          </dynamics>
        </axis>
      </joint>
      <link name='RR_thigh'>
        <pose relative_to='RR_thigh_joint'>0 0 0 0 -0 0</pose>
        <inertial>
          <pose>-0.003237 0.022327 -0.027326 0 -0 0</pose>
          <mass>1.013</mass>
          <inertia>
            <ixx>0.00552906</ixx>
            <ixy>-4.825e-06</ixy>
            <ixz>0.000343869</ixz>
            <iyy>0.00513934</iyy>
            <iyz>-2.2448e-05</iyz>
            <izz>0.00136779</izz>
          </inertia>
        </inertial>
        <collision name='RR_thigh_collision'>
          <pose>0 0 -0.1 3.14159 1.57079 3.14159</pose>
          <geometry>
            <box>
              <size>0.2 0.0245 0.034</size>
            </box>
          </geometry>
          <max_contacts>10</max_contacts>
          <surface>
            <contact>
              <ode/>
            </contact>
            <bounce/>
            <friction>
              <torsional>
                <ode/>
              </torsional>
              <ode/>
            </friction>
          </surface>
        </collision>
        <visual name='RR_thigh_visual'>
          <pose>0 0 0 0 -0 0</pose>
          <geometry>
            <mesh>
              <scale>1 1 1</scale>
              <uri>/home/danya/thes/a1_sim_py/src/a1_description/meshes/thigh_mirror.dae</uri>
            </mesh>
          </geometry>
        </visual>
        <self_collide>0</self_collide>
        <enable_wind>0</enable_wind>
        <kinematic>0</kinematic>
      </link>
      <joint name='RR_calf_joint' type='revolute'>
        <pose relative_to='RR_thigh'>0 0 -0.2 0 -0 0</pose>
        <parent>RR_thigh</parent>
        <child>RR_calf</child>
        <axis>
          <xyz>0 1 0</xyz>
          <limit>
            <lower>-2.69653</lower>
            <upper>-0.916298</upper>
            <effort>55</effort>
            <velocity>28.6</velocity>
          </limit>
          <dynamics>
            <damping>0</damping>
            <friction>0</friction>
            <spring_reference>0</spring_reference>
            <spring_stiffness>0</spring_stiffness>
          </dynamics>
        </axis>
      </joint>
      <link name='RR_calf'>
        <pose relative_to='RR_calf_joint'>0 0 0 0 -0 0</pose>
        <inertial>
          <pose>0.004727 0 -0.131975 0 -0 0</pose>
          <mass>0.226</mass>
          <inertia>
            <ixx>0.00338557</ixx>
            <ixy>0</ixy>
            <ixz>-0.000167427</ixz>
            <iyy>0.00340344</iyy>
            <iyz>0</iyz>
            <izz>4.38509e-05</izz>
          </inertia>
        </inertial>
        <collision name='RR_calf_collision'>
          <pose>0 0 -0.1 3.14159 1.57079 3.14159</pose>
          <geometry>
            <box>
              <size>0.2 0.016 0.016</size>
            </box>
          </geometry>
          <max_contacts>10</max_contacts>
          <surface>
            <contact>
              <ode/>
            </contact>
            <bounce/>
            <friction>
              <torsional>
                <ode/>
              </torsional>
              <ode/>
            </friction>
          </surface>
        </collision>
        <collision name='RR_calf_fixed_joint_lump__RR_foot_collision_1'>
          <pose>0 0 -0.2 0 -0 0</pose>
          <geometry>
            <sphere>
              <radius>0.02</radius>
            </sphere>
          </geometry>
          <surface>
            <contact>
              <ode>
                <kp>1e+06</kp>
                <kd>100</kd>
                <min_depth>0.0002</min_depth>
              </ode>
            </contact>
            <friction>
              <ode>
                <mu>1</mu>
                <mu2>1</mu2>
              </ode>
              <torsional>
                <ode/>
              </torsional>
            </friction>
            <bounce/>
          </surface>
          <max_contacts>10</max_contacts>
        </collision>
        <visual name='RR_calf_visual'>
          <pose>0 0 0 0 -0 0</pose>
          <geometry>
            <mesh>
              <scale>1 1 1</scale>
              <uri>/home/danya/thes/a1_sim_py/src/a1_description/meshes/calf.dae</uri>
            </mesh>
          </geometry>
        </visual>
        <visual name='RR_calf_fixed_joint_lump__RR_foot_visual_1'>
          <pose>0 0 -0.2 0 -0 0</pose>
          <geometry>
            <sphere>
              <radius>0.01</radius>
            </sphere>
          </geometry>
        </visual>
        <self_collide>0</self_collide>
        <enable_wind>0</enable_wind>
        <kinematic>0</kinematic>
      </link>
      <plugin name='gazebo_ros_control' filename='libgazebo_ros_control.so'>
        <robotNamespace>a1_gazebo</robotNamespace>
      </plugin>
      <plugin name='p3d_base_controller' filename='libgazebo_ros_p3d.so'>
        <alwaysOn>1</alwaysOn>
        <updateRate>50.0</updateRate>
        <topicName>a1/odom</topicName>
        <gaussianNoise>0.01</gaussianNoise>
        <frameName>world</frameName>
        <xyzOffsets>0 0 0</xyzOffsets>
        <rpyOffsets>0 0 0</rpyOffsets>
        <robotNamespace>/</robotNamespace>
        <bodyName>base</bodyName>
        <xyzOffset>0 0 0</xyzOffset>
        <rpyOffset>0 -0 0</rpyOffset>
        <ignition::corrected_offsets>1</ignition::corrected_offsets>
      </plugin>
      <plugin name='joint_state_publisher' filename='libgazebo_ros_joint_state_publisher.so'>
        <robotNamespace>a1_gazebo</robotNamespace>
        <jointName>FR_hip_joint, FR_thigh_joint, FR_calf_joint, FL_hip_joint, FL_thigh_joint, FL_calf_joint, RR_hip_joint, RR_thigh_joint, RR_calf_joint, RL_hip_joint, RL_thigh_joint, RL_calf_joint</jointName>
        <updateRate>100</updateRate>
      </plugin>
      <frame name='imu_joint' attached_to='trunk'>
        <pose>0 0 0 0 -0 0</pose>
      </frame>
      <frame name='imu_link' attached_to='imu_joint'/>
      <frame name='floating_base' attached_to='base'>
        <pose>0 0 0 0 -0 0</pose>
      </frame>
      <frame name='trunk' attached_to='floating_base'/>
      <frame name='FL_hip_fixed' attached_to='FL_hip'>
        <pose>0 0.081 0 0 -0 0</pose>
      </frame>
      <frame name='FL_thigh_shoulder' attached_to='FL_hip_fixed'/>
      <frame name='FL_foot_fixed' attached_to='FL_calf'>
        <pose>0 0 -0.2 0 -0 0</pose>
      </frame>
      <frame name='FL_foot' attached_to='FL_foot_fixed'/>
      <frame name='FR_hip_fixed' attached_to='FR_hip'>
        <pose>0 -0.081 0 0 -0 0</pose>
      </frame>
      <frame name='FR_thigh_shoulder' attached_to='FR_hip_fixed'/>
      <frame name='FR_foot_fixed' attached_to='FR_calf'>
        <pose>0 0 -0.2 0 -0 0</pose>
      </frame>
      <frame name='FR_foot' attached_to='FR_foot_fixed'/>
      <frame name='RL_hip_fixed' attached_to='RL_hip'>
        <pose>0 0.081 0 0 -0 0</pose>
      </frame>
      <frame name='RL_thigh_shoulder' attached_to='RL_hip_fixed'/>
      <frame name='RL_foot_fixed' attached_to='RL_calf'>
        <pose>0 0 -0.2 0 -0 0</pose>
      </frame>
      <frame name='RL_foot' attached_to='RL_foot_fixed'/>
      <frame name='RR_hip_fixed' attached_to='RR_hip'>
        <pose>0 -0.081 0 0 -0 0</pose>
      </frame>
      <frame name='RR_thigh_shoulder' attached_to='RR_hip_fixed'/>
      <frame name='RR_foot_fixed' attached_to='RR_calf'>
        <pose>0 0 -0.2 0 -0 0</pose>
      </frame>
      <frame name='RR_foot' attached_to='RR_foot_fixed'/>
      <pose>0 0 0.3 0 -0 0</pose>
    </model>
    <model name='unit_cylinder'>
      <pose>9.63009 -1.91032 0.5 0 -0 0</pose>
      <link name='link'>
        <inertial>
          <mass>1</mass>
          <inertia>
            <ixx>0.145833</ixx>
            <ixy>0</ixy>
            <ixz>0</ixz>
            <iyy>0.145833</iyy>
            <iyz>0</iyz>
            <izz>0.125</izz>
          </inertia>
          <pose>0 0 0 0 -0 0</pose>
        </inertial>
        <collision name='collision'>
          <geometry>
            <cylinder>
              <radius>0.5</radius>
              <length>1</length>
            </cylinder>
          </geometry>
          <max_contacts>10</max_contacts>
          <surface>
            <contact>
              <ode/>
            </contact>
            <bounce/>
            <friction>
              <torsional>
                <ode/>
              </torsional>
              <ode/>
            </friction>
          </surface>
        </collision>
        <visual name='visual'>
          <geometry>
            <cylinder>
              <radius>0.5</radius>
              <length>1</length>
            </cylinder>
          </geometry>
          <material>
            <script>
              <name>Gazebo/Grey</name>
              <uri>file://media/materials/scripts/gazebo.material</uri>
            </script>
          </material>
        </visual>
        <self_collide>0</self_collide>
        <enable_wind>0</enable_wind>
        <kinematic>0</kinematic>
      </link>
    </model>
    <state world_name='default'>
      <sim_time>344 633000000</sim_time>
      <real_time>106 731249211</real_time>
      <wall_time>1738120012 884577568</wall_time>
      <iterations>45863</iterations>
      <model name='a1_gazebo'>
        <pose>-10.0316 0.278163 0.350911 -0.000973 -0.004217 -0.361609</pose>
        <scale>1 1 1</scale>
        <link name='FL_calf'>
          <pose>-9.94834 0.386912 0.211931 -0.013366 -1.01899 -0.350071</pose>
          <velocity>0.009524 -0.003455 -0.004993 -0.017572 0.040205 0.008026</velocity>
          <acceleration>-1.19406 1.73198 7.76477 2.70811 -0.157554 2.12838</acceleration>
          <wrench>-0.269858 0.391428 1.75484 0 -0 0</wrench>
        </link>
        <link name='FL_hip'>
          <pose>-9.84376 0.257382 0.351637 -0.006468 -0.004218 -0.361647</pose>
          <velocity>0.007571 0.000288 2.9e-05 -0.014856 0.006776 0.002857</velocity>
          <acceleration>-0.076015 0.158158 1.41789 1.73041 -0.360512 -2.07082</acceleration>
          <wrench>-0.052907 0.110078 0.986851 0 -0 0</wrench>
        </link>
        <link name='FL_thigh'>
          <pose>-9.81367 0.33693 0.35109 -0.009292 0.801208 -0.36835</pose>
          <velocity>0.007131 0.000464 -0.001278 -0.024093 -0.017856 0.003124</velocity>
          <acceleration>-0.532386 0.55795 2.4727 0.478926 -1.38283 2.00394</acceleration>
          <wrench>-0.539307 0.565203 2.50485 0 -0 0</wrench>
        </link>
        <link name='FR_calf'>
          <pose>-10.0406 0.140105 0.21166 -0.002992 -1.02887 -0.359213</pose>
          <velocity>0.008796 -0.005239 0.000149 0.01763 0.041078 -0.004904</velocity>
          <acceleration>-1.40399 -1.12006 8.18767 1.35598 -0.815708 0.036482</acceleration>
          <wrench>-0.317302 -0.253133 1.85041 0 -0 0</wrench>
        </link>
        <link name='FR_hip'>
          <pose>-9.87702 0.169462 0.351728 -0.00196 -0.004217 -0.361584</pose>
          <velocity>0.007997 0.000111 1.4e-05 -0.025105 0.010651 0.007906</velocity>
          <acceleration>-0.100394 0.089896 1.12291 -2.2417 -1.55245 -0.990478</acceleration>
          <wrench>-0.069874 0.062568 0.781543 0 -0 0</wrench>
        </link>
        <link name='FR_thigh'>
          <pose>-9.90711 0.089913 0.351896 -0.002796 0.793719 -0.363586</pose>
          <velocity>0.0083 -1.8e-05 0.002476 -0.030951 -0.00478 0.007995</velocity>
          <acceleration>-0.951363 -0.078968 2.94702 -2.15065 -1.43556 -0.461825</acceleration>
          <wrench>-0.963731 -0.079995 2.98534 0 -0 0</wrench>
        </link>
        <link name='RL_calf'>
          <pose>-10.3015 0.523808 0.226989 0.029958 -0.927108 -0.385546</pose>
          <velocity>0.012939 -0.004956 -0.009185 0.013052 0.05268 0.006734</velocity>
          <acceleration>-1.30489 0.06765 3.75423 1.15321 0.415224 1.18291</acceleration>
          <wrench>-0.294905 0.015289 0.848455 0 -0 0</wrench>
        </link>
        <link name='RL_hip'>
          <pose>-10.1861 0.386864 0.350093 0.017861 -0.004217 -0.361594</pose>
          <velocity>0.006946 -0.001368 0.000435 -0.004201 0.002815 0.005124</velocity>
          <acceleration>-0.055102 0.181615 -0.235718 -0.466056 -0.868771 1.8681</acceleration>
          <wrench>-0.038351 0.126404 -0.16406 0 -0 0</wrench>
        </link>
        <link name='RL_thigh'>
          <pose>-10.156 0.466404 0.351612 0.028654 0.897739 -0.339112</pose>
          <velocity>0.006564 -0.001214 3.7e-05 -0.025632 -0.053909 0.003982</velocity>
          <acceleration>-0.280993 0.24545 0.108217 1.55134 1.23789 -0.367294</acceleration>
          <wrench>-0.284646 0.248641 0.109623 0 -0 0</wrench>
        </link>
        <link name='RR_calf'>
          <pose>-10.3945 0.272549 0.224211 -0.021437 -0.953455 -0.344291</pose>
          <velocity>0.012784 -0.004675 -0.006393 0.017358 0.065027 0.005272</velocity>
          <acceleration>-0.669924 -0.114263 4.03275 -1.05159 -0.897096 -2.87767</acceleration>
          <wrench>-0.151403 -0.025823 0.911401 0 -0 0</wrench>
        </link>
        <link name='RR_hip'>
          <pose>-10.2193 0.298944 0.350185 -0.012649 -0.004216 -0.361611</pose>
          <velocity>0.007369 -0.001535 0.000413 -0.001876 0.001929 0.005081</velocity>
          <acceleration>-0.069943 0.174384 -0.582546 -0.596437 -0.306526 1.85575</acceleration>
          <wrench>-0.04868 0.121372 -0.405452 0 -0 0</wrench>
        </link>
        <link name='RR_thigh'>
          <pose>-10.2494 0.219402 0.351263 -0.019923 0.882273 -0.377043</pose>
          <velocity>0.007764 -0.001669 0.000604 -0.018208 -0.041761 0.004664</velocity>
          <acceleration>-0.244125 0.266804 -0.120421 3.05349 0.667798 2.63279</acceleration>
          <wrench>-0.247299 0.270272 -0.121987 0 -0 0</wrench>
        </link>
        <link name='base'>
          <pose>-10.0316 0.278163 0.350911 -0.000973 -0.004217 -0.361609</pose>
          <velocity>0.007472 -0.000626 0.000217 0.000572 0.000979 0.004827</velocity>
          <acceleration>-0.077783 0.152826 0.477587 0.305948 0.454261 2.99637</acceleration>
          <wrench>-0.366671 0.720424 2.25135 0 -0 0</wrench>
        </link>
      </model>
      <model name='box'>
        <pose>5.64228 12.0558 0.414063 0 0.1 0</pose>
        <scale>1 1 1</scale>
        <link name='link'>
          <pose>5.64228 12.0558 0.414063 0 0.1 0</pose>
          <velocity>0 0 0 0 -0 0</velocity>
          <acceleration>0 0 0 0 -0 0</acceleration>
          <wrench>0 0 0 0 -0 0</wrench>
        </link>
      </model>
      <model name='ground_plane'>
        <pose>0 0 0 0 -0 0</pose>
        <scale>1 1 1</scale>
        <link name='link'>
          <pose>0 0 0 0 -0 0</pose>
          <velocity>0 0 0 0 -0 0</velocity>
          <acceleration>0 0 0 0 -0 0</acceleration>
          <wrench>0 0 0 0 -0 0</wrench>
        </link>
      </model>
      <model name='ski'>
        <pose>-10.0558 0.274589 -0.00015 0.005351 -5.5e-05 2.81454</pose>
        <scale>1 1 1</scale>
        <link name='base_link'>
          <pose>-10.0558 0.274589 -0.00015 0.005351 -5.5e-05 2.81454</pose>
          <velocity>0.006087 -0.00381 0.006693 -0.014018 -0.015786 -0.006372</velocity>
          <acceleration>0.266074 -0.268507 9.84227 -2.15589 0.026448 0.86564</acceleration>
          <wrench>0.847341 -0.855087 31.3437 0 -0 0</wrench>
        </link>
        <link name='tr0'>
          <pose>-10.291 0.354533 0.024926 -0.001356 0.379725 2.7992</pose>
          <velocity>0.005831 -0.002303 0.002004 0.004361 0.056356 -0.090054</velocity>
          <acceleration>1.06612 -2.80425 3.04615 1.21455 -0.637361 1.49626</acceleration>
          <wrench>0.058328 -0.153423 0.166658 0 -0 0</wrench>
        </link>
        <link name='tr1'>
          <pose>-9.82048 0.194899 0.024915 0.00103 0.381876 -0.308786</pose>
          <velocity>0.005303 -0.003832 0.008647 -0.069843 0.09892 -0.089161</velocity>
          <acceleration>3.06825 1.80844 7.51203 2.33319 0.676235 1.39917</acceleration>
          <wrench>0.167867 0.098942 0.410991 0 -0 0</wrench>
        </link>
        <link name='wh0'>
          <pose>-10.2646 0.42893 0.025 0.000353 -0.846377 2.79952</pose>
          <velocity>0.012644 -0.004635 0.000442 0.205208 0.532022 -0.087706</velocity>
          <acceleration>14.6405 -6.14192 0.833054 0.373309 -1.33021 2.84618</acceleration>
          <wrench>0.718525 -0.301433 0.040885 0 -0 0</wrench>
        </link>
        <link name='wh1'>
          <pose>-10.3175 0.280135 0.024957 -0.000415 -0.062025 2.79952</pose>
          <velocity>-0.002001 0.000806 0.002111 -0.049602 -0.115396 -0.097344</velocity>
          <acceleration>-14.4902 3.65255 2.48844 1.15651 -1.13713 1.11854</acceleration>
          <wrench>-0.711152 0.17926 0.122128 0 -0 0</wrench>
        </link>
        <link name='wh2'>
          <pose>-9.79646 0.270133 0.024965 0.000579 0.055419 2.83235</pose>
          <velocity>0.013027 -0.004505 0.00209 0.192836 0.529025 -0.034592</velocity>
          <acceleration>-6.56533 6.99869 -1.22506 -0.141421 -0.091818 -2.12662</acceleration>
          <wrench>-0.322213 0.343482 -0.060124 0 -0 0</wrench>
        </link>
        <link name='wh3'>
          <pose>-9.84449 0.119679 0.024973 -3.14126 0.533254 -0.308791</pose>
          <velocity>-0.005088 -0.004579 0.014698 0.178564 -0.206802 -0.068414</velocity>
          <acceleration>11.7301 -6.80685 -0.352562 -0.935001 0.043118 -0.005266</acceleration>
          <wrench>0.57569 -0.334066 -0.017303 0 -0 0</wrench>
        </link>
      </model>
      <model name='unit_cylinder'>
        <pose>-0.440054 -1.49731 0.499999 0 -0 0</pose>
        <scale>1 1 1</scale>
        <link name='link'>
          <pose>-0.440054 -1.49731 0.499999 0 -0 0</pose>
          <velocity>0 0 0 0 -0 0</velocity>
          <acceleration>0 0 -9.8 0 -0 0</acceleration>
          <wrench>0 0 -9.8 0 -0 0</wrench>
        </link>
      </model>
      <model name='unit_cylinder_0'>
        <pose>-0.467349 1.52212 0.499992 -3e-06 -4e-06 -0</pose>
        <scale>1 1 1</scale>
        <link name='link'>
          <pose>-0.467349 1.52212 0.499992 -3e-06 -4e-06 -0</pose>
          <velocity>0 0 0 0 -0 0</velocity>
          <acceleration>0 0 -9.8 0 -0 0</acceleration>
          <wrench>0 0 -9.8 0 -0 0</wrench>
        </link>
      </model>
      <light name='sun'>
        <pose>0 0 10 0 -0 0</pose>
      </light>
    </state>
    <gui fullscreen='0'>
      <camera name='user_camera'>
        <pose>-13.3087 -0.886646 1.55231 0 0.183315 0.018824</pose>
        <view_controller>orbit</view_controller>
        <projection_type>perspective</projection_type>
      </camera>
    </gui>
    <model name='unit_cylinder_0'>
      <pose>7.7273 -0.856623 0.5 0 -0 0</pose>
      <link name='link'>
        <inertial>
          <mass>1</mass>
          <inertia>
            <ixx>0.145833</ixx>
            <ixy>0</ixy>
            <ixz>0</ixz>
            <iyy>0.145833</iyy>
            <iyz>0</iyz>
            <izz>0.125</izz>
          </inertia>
          <pose>0 0 0 0 -0 0</pose>
        </inertial>
        <collision name='collision'>
          <geometry>
            <cylinder>
              <radius>0.5</radius>
              <length>1</length>
            </cylinder>
          </geometry>
          <max_contacts>10</max_contacts>
          <surface>
            <contact>
              <ode/>
            </contact>
            <bounce/>
            <friction>
              <torsional>
                <ode/>
              </torsional>
              <ode/>
            </friction>
          </surface>
        </collision>
        <visual name='visual'>
          <geometry>
            <cylinder>
              <radius>0.5</radius>
              <length>1</length>
            </cylinder>
          </geometry>
          <material>
            <script>
              <name>Gazebo/Grey</name>
              <uri>file://media/materials/scripts/gazebo.material</uri>
            </script>
          </material>
        </visual>
        <self_collide>0</self_collide>
        <enable_wind>0</enable_wind>
        <kinematic>0</kinematic>
      </link>
    </model>
  </world>
</sdf>
