<?xml version="1.0" encoding="utf-8"?>
<robot name="ski">

  <!-- Base Link (the deck of the skateboard) -->
  <link name="base_link">
    <inertial>
      <origin xyz="-2.2998E-07 9.74E-09 0.081029" rpy="0 0 0" />
      <mass value="3.1846" />
      <inertia ixx="0.049043" ixy="-1.5821E-08" ixz="-4.3995E-09" iyy="0.083631" iyz="1.8621E-10" izz="0.13258" />
    </inertial>
    <visual>
      <origin xyz="0 0 0" rpy="0 0 0" />
      <geometry>
        <mesh filename="package://ski/meshes/base_link.STL" />
      </geometry>
      <material name="deck_material">
        <color rgba="0.79216 0.81961 0.93333 1" />
      </material>
    </visual>
    <collision>
      <origin xyz="0 0 0" rpy="0 0 0" />
      <geometry>
        <mesh filename="package://ski/meshes/base_link.STL" />
      </geometry>
    </collision>
  </link>

  <!-- Front Truck (tr0) -->
  <link name="tr0">
    <inertial>
      <origin xyz="-0.0039479 1.3746E-05 0.002543" rpy="0 0 0" />
      <mass value="0.054711" />
      <inertia ixx="7.6178E-05" ixy="4.236E-09" ixz="-1.6794E-07" iyy="6.5079E-06" iyz="3.528E-09" izz="7.7065E-05" />
    </inertial>
    <visual>
      <origin xyz="0 0 0" rpy="0 0 0" />
      <geometry>
        <mesh filename="package://ski/meshes/tr0.STL" />
      </geometry>
      <material name="truck_material">
        <color rgba="0.79216 0.81961 0.93333 1" />
      </material>
    </visual>
    <collision>
      <origin xyz="0 0 0" rpy="0 0 0" />
      <geometry>
        <mesh filename="package://ski/meshes/tr0.STL" />
      </geometry>
    </collision>
  </link>

  <!-- Front Truck Joint (trj0) -->
  <joint name="trj0" type="revolute">
    <origin xyz="0.24845 0 0.025" rpy="0 0.38044 0" />
    <parent link="base_link" />
    <child link="tr0" />
    <axis xyz="0 0 -1" />
    <limit lower="-0.227799" upper="0.227799" effort="10" velocity="10" />
  </joint>

  <!-- Torsional Spring Plugin for trj0 -->
  <gazebo>
    <plugin name="trj0_torsional_spring" filename="libgazebo_joint_torsional_spring.so">
      <kx>20.0</kx>
      <set_point>0</set_point>
      <joint>trj0</joint>
    </plugin>
  </gazebo>

  <!-- Front Left Wheel (wh0) -->
  <link name="wh0">
    <inertial>
      <origin xyz="0 0 0" rpy="0 0 0" />
      <mass value="0.049078" />
      <inertia ixx="1.141E-05" ixy="0" ixz="0" iyy="1.6312E-05" iyz="0" izz="1.141E-05" />
    </inertial>
    <visual>
      <origin xyz="0 0 0" rpy="0 0 0" />
      <geometry>
        <mesh filename="package://ski/meshes/wh0.STL" />
      </geometry>
      <material name="wheel_material">
        <color rgba="0.79216 0.81961 0.93333 1" />
      </material>
    </visual>
    <collision>
      <origin xyz="0 0 0" rpy="0 0 0" />
      <geometry>
        <mesh filename="package://ski/meshes/wh0.STL" />
      </geometry>
    </collision>
  </link>

  <!-- Front Left Wheel Joint (whj0) -->
  <joint name="whj0" type="continuous">
    <origin xyz="0 -0.079 0" rpy="0 -0.38044 0" />
    <parent link="tr0" />
    <child link="wh0" />
    <axis xyz="0 1 0" />
  </joint>

  <!-- Front Right Wheel (wh1) -->
  <link name="wh1">
    <inertial>
      <origin xyz="0 0 0" rpy="0 0 0" />
      <mass value="0.049078" />
      <inertia ixx="1.141E-05" ixy="0" ixz="0" iyy="1.6312E-05" iyz="0" izz="1.141E-05" />
    </inertial>
    <visual>
      <origin xyz="0 0 0" rpy="0 0 0" />
      <geometry>
        <mesh filename="package://ski/meshes/wh1.STL" />
      </geometry>
    </visual>
    <collision>
      <origin xyz="0 0 0" rpy="0 0 0" />
      <geometry>
        <mesh filename="package://ski/meshes/wh1.STL" />
      </geometry>
    </collision>
  </link>

  <!-- Front Right Wheel Joint (whj1) -->
  <joint name="whj1" type="continuous">
    <origin xyz="0 0.079 0" rpy="0 -0.38044 0" />
    <parent link="tr0" />
    <child link="wh1" />
    <axis xyz="0 1 0" />
  </joint>

  <!-- Rear Truck (tr1) -->
  <link name="tr1">
    <inertial>
      <origin xyz="0 0 0" rpy="0 0 0" />
      <mass value="0.054711" />
      <inertia ixx="7.6178E-05" ixy="0" ixz="0" iyy="6.5079E-06" iyz="0" izz="7.7065E-05" />
    </inertial>
    <visual>
      <origin xyz="0 0 0" rpy="0 0 0" />
      <geometry>
        <mesh filename="package://ski/meshes/tr1.STL" />
      </geometry>
    </visual>
    <collision>
      <origin xyz="0 0 0" rpy="0 0 0" />
      <geometry>
        <mesh filename="package://ski/meshes/tr1.STL" />
      </geometry>
    </collision>
  </link>

  <!-- Rear Truck Joint (trj1) -->
  <joint name="trj1" type="revolute">
    <origin xyz="-0.24845 0 0.025" rpy="0 0.38044 3.1416" />
    <parent link="base_link" />
    <child link="tr1" />
    <axis xyz="0 0 -1" />
    <limit lower="-0.227799" upper="0.227799" effort="10" velocity="10" />
  </joint>

  <!-- Torsional Spring Plugin for trj1 -->
  <gazebo>
    <plugin name="trj1_torsional_spring" filename="libgazebo_joint_torsional_spring.so">
      <kx>20.0</kx>
      <set_point>0</set_point>
      <joint>trj1</joint>
    </plugin>
  </gazebo>

  <!-- Rear Left Wheel (wh2) -->
  <link name="wh2">
    <inertial>
      <origin xyz="0 0 0" rpy="0 0 0" />
      <mass value="0.049078" />
      <inertia ixx="1.141E-05" ixy="0" ixz="0" iyy="1.6312E-05" iyz="0" izz="1.141E-05" />
    </inertial>
    <visual>
      <origin xyz="0 0 0" rpy="0 0 0" />
      <geometry>
        <mesh filename="package://ski/meshes/wh2.STL" />
      </geometry>
    </visual>
    <collision>
      <origin xyz="0 0 0" rpy="0 0 0" />
      <geometry>
        <mesh filename="package://ski/meshes/wh2.STL" />
      </geometry>
    </collision>
  </link>

  <!-- Rear Left Wheel Joint (whj2) -->
  <joint name="whj2" type="continuous">
    <origin xyz="0 0.079 0" rpy="0 0.38044 3.1416" />
    <parent link="tr1" />
    <child link="wh2" />
    <axis xyz="0 1 0" />
  </joint>

  <!-- Rear Right Wheel (wh3) -->
  <link name="wh3">
    <inertial>
      <origin xyz="0 0 0" rpy="0 0 0" />
      <mass value="0.049078" />
      <inertia ixx="1.141E-05" ixy="0" ixz="0" iyy="1.6312E-05" iyz="0" izz="1.141E-05" />
    </inertial>
    <visual>
      <origin xyz="0 0 0" rpy="0 0 0" />
      <geometry>
        <mesh filename="package://ski/meshes/wh3.STL" />
      </geometry>
    </visual>
    <collision>
      <origin xyz="0 0 0" rpy="0 0 0" />
      <geometry>
        <mesh filename="package://ski/meshes/wh3.STL" />
      </geometry>
    </collision>
  </link>

  <!-- Rear Right Wheel Joint (whj3) -->
  <joint name="whj3" type="continuous">
    <origin xyz="0 -0.079 0" rpy="0 0.38044 3.1416" />
    <parent link="tr1" />
    <child link="wh3" />
    <axis xyz="0 1 0" />
  </joint>
</robot>
